require('../../spec_helper')

braintree = specHelper.braintree
{Config} = require('../../../lib/braintree/config')
{Http} = require('../../../lib/braintree/http')
{Environment} = require('../../../lib/braintree/environment')

describe "Http", ->
  describe "request", ->
    it "returns a ServerError for 500s", (done) ->
      http = new Http(new Config(specHelper.defaultConfig))
      http.post '/test/error', '', (err, response) ->
        assert.equal(err.type, braintree.errorTypes.serverError)

        done()

    it "returns a down for maintenance error for 503s", (done) ->
      http = new Http(new Config(specHelper.defaultConfig))
      http.post '/test/maintenance', '', (err, response) ->
        assert.equal(err.type, braintree.errorTypes.downForMaintenanceError)

        done()

    it "can hit the sandbox", (done) ->
      @timeout 10000

      http = new Http(new Config(
        environment: braintree.Environment.Sandbox
        merchantId: 'node'
        publicKey: 'node'
        privateKey: 'node'
      ))

      http.get '/not_found', (err, response) ->
        assert.equal(err.type, braintree.errorTypes.notFoundError)

        done()

    it "can hit production", (done) ->
      @timeout 10000

      http = new Http(new Config(
        environment: braintree.Environment.Production
        merchantId: 'node'
        publicKey: 'node'
        privateKey: 'node'
      ))

      http.get '/not_found', (err, response) ->
        assert.equal(err.type, braintree.errorTypes.notFoundError)

        done()

    xit "returns errors to the callback", (done) ->
      # This test only fails due to the 'done' callback being called twice.
      # Invalid test, which randomly fails.
      http = new Http(new Config(
        environment: new Environment('not_a_subdomain.braintreegateway.com', '12345', false)
        merchantId: 'node'
        publicKey: 'node'
        privateKey: 'node'
      ))

      http.timeout = 1
      http.get '/not_a_real_url', (err, response) ->
        assert.equal(err.type, braintree.errorTypes.unexpectedError)
